Traceback (most recent call last):
  File "/opt/hostedtoolcache/Python/3.10.18/x64/lib/python3.10/site-packages/jupyter_core/utils/__init__.py", line 154, in wrapped
    asyncio.get_running_loop()
RuntimeError: no running event loop

During handling of the above exception, another exception occurred:

Traceback (most recent call last):
  File "/opt/hostedtoolcache/Python/3.10.18/x64/lib/python3.10/site-packages/jupyter_cache/executors/utils.py", line 58, in single_nb_execution
    executenb(
  File "/opt/hostedtoolcache/Python/3.10.18/x64/lib/python3.10/site-packages/nbclient/client.py", line 1319, in execute
    return NotebookClient(nb=nb, resources=resources, km=km, **kwargs).execute()
  File "/opt/hostedtoolcache/Python/3.10.18/x64/lib/python3.10/site-packages/jupyter_core/utils/__init__.py", line 158, in wrapped
    return loop.run_until_complete(inner)
  File "/opt/hostedtoolcache/Python/3.10.18/x64/lib/python3.10/asyncio/base_events.py", line 649, in run_until_complete
    return future.result()
  File "/opt/hostedtoolcache/Python/3.10.18/x64/lib/python3.10/site-packages/nbclient/client.py", line 709, in async_execute
    await self.async_execute_cell(
  File "/opt/hostedtoolcache/Python/3.10.18/x64/lib/python3.10/site-packages/nbclient/client.py", line 1062, in async_execute_cell
    await self._check_raise_for_error(cell, cell_index, exec_reply)
  File "/opt/hostedtoolcache/Python/3.10.18/x64/lib/python3.10/site-packages/nbclient/client.py", line 918, in _check_raise_for_error
    raise CellExecutionError.from_cell_and_msg(cell, exec_reply_content)
nbclient.exceptions.CellExecutionError: An error occurred while executing the following cell:
------------------
from causalkit.eda import CausalEDA
eda = CausalEDA(causal_data)
------------------


[0;31m---------------------------------------------------------------------------[0m
[0;31mModuleNotFoundError[0m                       Traceback (most recent call last)
Cell [0;32mIn[2], line 1[0m
[0;32m----> 1[0m [38;5;28;01mfrom[39;00m[38;5;250m [39m[38;5;21;01mcausalkit[39;00m[38;5;21;01m.[39;00m[38;5;21;01meda[39;00m[38;5;250m [39m[38;5;28;01mimport[39;00m CausalEDA
[1;32m      2[0m eda [38;5;241m=[39m CausalEDA(causal_data)

File [0;32m~/work/CausalKit/CausalKit/causalkit/eda/__init__.py:1[0m
[0;32m----> 1[0m [38;5;28;01mfrom[39;00m[38;5;250m [39m[38;5;21;01m.[39;00m[38;5;21;01meda[39;00m[38;5;250m [39m[38;5;28;01mimport[39;00m CausalEDA, CausalDataLite
[1;32m      3[0m __all__ [38;5;241m=[39m [[38;5;124m"[39m[38;5;124mCausalEDA[39m[38;5;124m"[39m, [38;5;124m"[39m[38;5;124mCausalDataLite[39m[38;5;124m"[39m]

File [0;32m~/work/CausalKit/CausalKit/causalkit/eda/eda.py:38[0m
[1;32m     36[0m [38;5;28;01mfrom[39;00m[38;5;250m [39m[38;5;21;01msklearn[39;00m[38;5;21;01m.[39;00m[38;5;21;01mpipeline[39;00m[38;5;250m [39m[38;5;28;01mimport[39;00m Pipeline
[1;32m     37[0m [38;5;28;01mfrom[39;00m[38;5;250m [39m[38;5;21;01msklearn[39;00m[38;5;21;01m.[39;00m[38;5;21;01mlinear_model[39;00m[38;5;250m [39m[38;5;28;01mimport[39;00m LogisticRegression, LinearRegression
[0;32m---> 38[0m [38;5;28;01mfrom[39;00m[38;5;250m [39m[38;5;21;01mcatboost[39;00m[38;5;250m [39m[38;5;28;01mimport[39;00m CatBoostClassifier, CatBoostRegressor
[1;32m     39[0m [38;5;28;01mimport[39;00m[38;5;250m [39m[38;5;21;01mmatplotlib[39;00m[38;5;21;01m.[39;00m[38;5;21;01mpyplot[39;00m[38;5;250m [39m[38;5;28;01mas[39;00m[38;5;250m [39m[38;5;21;01mplt[39;00m
[1;32m     42[0m [38;5;28;01mclass[39;00m[38;5;250m [39m[38;5;21;01mPropensityModel[39;00m:

[0;31mModuleNotFoundError[0m: No module named 'catboost'

